Workbook

Sheet Instructions
A1: Self-Funded Transition & Optimization Roadmap Tool
B2: CCIG | Internal Planning Tool
B4: What this is
B5: One selection on the Client Setup tab drives everything else: a visual roadmap cover page, and four short, audience-specific checklists (HR, Finance, Signing, and the Full Roadmap for anyone who wants everything). Each checklist item is a single scannable line; click the small [+] to its left to expand the full explanation only when you need it.
B10: How to use it, in order
B11: 1. Client Setup | C11: Enter the client's name and engagement type, then mark Yes/No for every plan component and Savings Engine vendor. This is the only tab you edit per client.
B12: 2. Roadmap Overview | C12: The client-facing cover page: a visual timeline plus one-click links into each checklist. This is what you lead with.
B13: 3. HR / Finance / Signing Checklists | C13: Short, audience-specific checklists that rebuild themselves from your Setup selections. Not-applicable items grey out automatically; click the Applicable filter and choose Yes for the clean client view. Expand any row's [+] for the full explanation.
B14: 4. Full Roadmap | C14: The same content, unfiltered by audience, for anyone who wants the complete picture in one place.
B15: 5. Document & Task Library | C15: The master content behind every checklist. Edit Description / Short Line / What to Expect here to refine language; changes flow into every future roadmap automatically.
B16: 6. Project Tracker | C16: Your own internal status rollup. Not meant for the client.
B18: Legend
C19: Yellow = a cell you fill in or select
C20: Grey = not applicable to this client (auto-calculated). Click the Applicable filter above the table and choose Yes to hide these rows.
B21: [+] | C21: Click to expand the full explanation for that line
B23: Reusing this for a new client
B24: Save a copy of this workbook per client (e.g. "Acme Co - SF Transition Roadmap.xlsx"). Reset the Client Setup tab, and every other tab rebuilds itself.

Sheet Client Setup
A1: Client Setup
B2: The only tab you edit per client. Everything else builds itself from here.
B4: Client Name | C4: Example Employer, Inc.
B5: Plan / Renewal Effective Date
B6: Prepared By | C6: CCIG Benefits Team
B7: Date Prepared
B8: Engagement Type | C8: New to Self-Funding
A10: CORE PROGRAM COMPONENTS
B11: Key | C11: Component | D11: Include?
B12: TPA_ADMIN | C12: TPA Administrative Services | D12: Yes
B13: STOP_LOSS | C13: Stop-Loss Coverage | D13: Yes
B14: PBM | C14: Pharmacy Benefit Manager (PBM) | D14: Yes
B15: CAPTIVE | C15: Captive Participation | D15: No
A17: COST CONTAINMENT / SAVINGS ENGINE SOLUTIONS
B18: Key | C18: Vendor / Solution | D18: Include?
B19: CC_CANCERCARE | C19: CancerCare - cancer care navigation | D19: No
B20: CC_EHEALTH | C20: eHealth - Medicare/ACA enrollment | D20: No
B21: CC_FIRSTSTOP | C21: First Stop Health - virtual primary/urgent care | D21: No
B22: CC_FOUND | C22: Found - weight & GLP-1 cost management | D22: No
B23: CC_HUSK | C23: HUSK - wellness (nutrition, mental health, rewards) | D23: No
B24: CC_LYRA | C24: Lyra Select - mental health | D24: No
B25: CC_PHIA | C25: The Phia Group - benefit compliance support | D25: No
B26: CC_PROGENY | C26: Progeny Health - neonatal intensive care management | D26: No
B27: CC_RENALOGIC | C27: Renalogic - chronic kidney disease & dialysis | D27: No
B28: CC_RIGHTWAY | C28: Rightway - surgeries, imaging & care navigation | D28: No
B29: CC_SMARTCONNECT | C29: SmartConnect (powered by SmartMatch) - Medicare enrollment | D29: No
... B31: CC_VALENZ | C31: Valenz Health - cost containment & claims | D31: No
A33: OPTIONAL ITEMS
B34: Key | C34: Item | D34: Include?
B35: FIN_COVERAGE_CALL | C35: Finance: Coverage Determination Calls (optional) | D35: No
A37: CALCULATED (do not edit)
B38: ANY_CC | C38: Any Cost Containment / Savings Engine solution selected? | D38: =IF(COUNTIF(D19:D31,"Yes")>0,"Yes","No") -> No

Sheet Roadmap Overview
A1: Your Path to a Self-Funded Plan
B2: ="Prepared for "&'Client Setup'!$C$4&" | "&'Client Setup'!$C$8 -> Prepared for Example Employer, Inc. | New to Self-Funding
B16: This is the full path from today to go-live. Five phases, each with its own short checklist. Nothing below requires more than a click to open, and every item tells you what it is and what to expect before you need to ask.
B20: Jump to your checklist
B21: → HR Checklist
B22: Open enrollment setup and vendor calls
B23: → Finance Checklist
B24: Banking setup and funding calls
B25: → Signing Checklist
B26: Every document your CFO or Authorized Signer needs
B27: → Full Roadmap
B28: Everything, across every team, in one place

Sheet HR Checklist
A1: HR Checklist
A2: ="Prepared for "&'Client Setup'!$C$4&" | "&'Client Setup'!$C$8 -> Prepared for Example Employer, Inc. | New to Self-Funding
A3: Your open enrollment setup and vendor calls, in order. Once Setup is finished, click the Applicable filter above and choose Yes to hide anything that doesn't apply.
A5: Status | B5: Item | C5: What This Covers | D5: Applicable? | E5: Due Date
A6: 1. KICKOFF & IMPLEMENTATION CALLS
A7: Not Started | B7: =IF('Document & Task Library'!C5="","",'Document & Task Library'!C5) -> TPA & Benefit Design Calls | C7: =IF('Document & Task Library'!H5="","",'Document & Task Library'!H5) -> Finalizes plan design and claims setup with your TPA | D7: =IF('Document & Task Library'!E5="ALWAYS","Yes",IFERROR(INDEX('Client Setup'!$D$12:$D$38,MATCH('Document & Task Library'!E5,'Client Setup'!$B$12:$B$38,0)),"No")) -> Yes
B8: ="Why it matters: "&'Document & Task Library'!I5&" What to expect: "&'Document & Task Library'!J5 -> Why it matters: Kickoff calls with the Third Party Administrator to finalize plan design, eligibility rules, and claims administration setup ahead of the effective date. What to expect: 2-4 sessions of 60-90 minutes over the first 3-4 weeks. Have current plan documents and eligibility file specs ready.
A9: Not Started | B9: =IF('Document & Task Library'!C6="","",'Document & Task Library'!C6) -> PBM Implementation Calls | C9: =IF('Document & Task Library'!H6="","",'Document & Task Library'!H6) -> Sets up your pharmacy formulary and member ID cards | D9: =IF('Document & Task Library'!E6="ALWAYS","Yes",IFERROR(INDEX('Client Setup'!$D$12:$D$38,MATCH('Document & Task Library'!E6,'Client Setup'!$B$12:$B$38,0)),"No")) -> Yes
B10: ="Why it matters: "&'Document & Task Library'!I6&" What to expect: "&'Document & Task Library'!J6 -> Why it matters: Implementation calls with the Pharmacy Benefit Manager to configure the formulary, prior authorization rules, and member ID cards. What to expect: 2-3 calls led by the PBM's implementation team. HR confirms member eligibility feed timing.
A11: Not Started | B11: =IF('Document & Task Library'!C7="","",'Document & Task Library'!C7) -> Cost Containment Vendor Calls | C11: =IF('Document & Task Library'!H7="","",'Document & Task Library'!H7) -> Kicks off each Savings Engine vendor you selected | D11: =IF('Document & Task Library'!E7="ALWAYS","Yes",IFERROR(INDEX('Client Setup'!$D$12:$D$38,MATCH('Document & Task Library'!E7,'Client Setup'!$B$12:$B$38,0)),"No")) -> No
B12: ="Why it matters: "&'Document & Task Library'!I7&" What to expect: "&'Document & Task Library'!J7 -> Why it matters: Individual kickoff calls with each selected Savings Engine vendor to set up enrollment, eligibility feeds, and member communications. What to expect: One call per selected vendor, typically 30-45 minutes, scheduled across the first month.
A13: Not Started | B13: =IF('Document & Task Library'!C8="","",'Document & Task Library'!C8) -> COBRA / FSA / HSA Calls | C13: =IF('Document & Task Library'!H8="","",'Document & Task Library'!H8) -> Transitions COBRA and FSA/HSA administration to the new plan | D13: =IF('Document & Task Library'!E8="ALWAYS","Yes",IFERROR(INDEX('Client Setup'!$D$12:$D$38,MATCH('Document & Task Library'!E8,'Client Setup'!$B$12:$B$38,0)),"No")) -> Yes
B14: ="Why it matters: "&'Document & Task Library'!I8&" What to expect: "&'Document & Task Library'!J8 -> Why it matters: Setup calls with the COBRA administrator and FSA/HSA vendor to transition existing participants and establish new account administration. What to expect: One call per vendor. HR provides the current COBRA participant list and FSA/HSA balances for transition.
A15: 3. HR WORKSTREAM - OPEN ENROLLMENT SETUP
A16: Not Started | B16: =IF('Document & Task Library'!C31="","",'Document & Task Library'!C31) -> Build HRIS for Open Enrollment | C16: =IF('Document & Task Library'!H31="","",'Document & Task Library'!H31) -> Loads new plan options and rates into your HRIS | D16: =IF('Document & Task Library'!E31="ALWAYS","Yes",IFERROR(INDEX('Client Setup'!$D$12:$D$38,MATCH('Document & Task Library'!E31,'Client Setup'!$B$12:$B$38,0)),"No")) -> Yes
B17: ="Why it matters: "&'Document & Task Library'!I31&" What to expect: "&'Document & Task Library'!J31 -> Why it matters: Configure the HR information system to reflect new plan options, rates, and eligibility rules ahead of open enrollment. What to expect: HR-owned. CCIG provides plan design specs to support setup.
A18: Not Started | B18: =IF('Document & Task Library'!C32="","",'Document & Task Library'!C32) -> Coordinate Open Enrollment Dates/Times | C18: =IF('Document & Task Library'!H32="","",'Document & Task Library'!H32) -> Locks the open enrollment window and meeting schedule | D18: =IF('Document & Task Library'!E32="ALWAYS","Yes",IFERROR(INDEX('Client Setup'!$D$12:$D$38,MATCH('Document & Task Library'!E32,'Client Setup'!$B$12:$B$38,0)),"No")) -> Yes
B19: ="Why it matters: "&'Document & Task Library'!I32&" What to expect: "&'Document & Task Library'!J32 -> Why it matters: Finalize the open enrollment window and schedule employee meetings or webinars. What to expect: Lock this in early; it drives every other communication deadline.
A20: Not Started | B20: =IF('Document & Task Library'!C33="","",'Document & Task Library'!C33) -> Review Open Enrollment Communications & Materials | C20: =IF('Document & Task Library'!H33="","",'Document & Task Library'!H33) -> Approves employee enrollment guides and emails | D20: =IF('Document & Task Library'!E33="ALWAYS","Yes",IFERROR(INDEX('Client Setup'!$D$12:$D$38,MATCH('Document & Task Library'!E33,'Client Setup'!$B$12:$B$38,0)),"No")) -> Yes
B21: ="Why it matters: "&'Document & Task Library'!I33&" What to expect: "&'Document & Task Library'!J33 -> Why it matters: Review and approve employee-facing enrollment guides, emails, and presentation materials before distribution. What to expect: CCIG drafts the first version; HR reviews for accuracy and tone.
A22: Not Started | B22: =IF('Document & Task Library'!C34="","",'Document & Task Library'!C34) -> Complete Open Enrollment Eligibility File | C22: =IF('Document & Task Library'!H34="","",'Document & Task Library'!H34) -> Submits the census file that loads member records | D22: =IF('Document & Task Library'!E34="ALWAYS","Yes",IFERROR(INDEX('Client Setup'!$D$12:$D$38,MATCH('Document & Task Library'!E34,'Client Setup'!$B$12:$B$38,0)),"No")) -> Yes
B23: ="Why it matters: "&'Document & Task Library'!I34&" What to expect: "&'Document & Task Library'!J34 -> Why it matters: Finalize and submit the eligibility census file the TPA and vendors use to load member records. What to expect: The single most time-sensitive HR deliverable. A late file delays ID cards and vendor access for members.
A24: 5. COST CONTAINMENT / SAVINGS ENGINE ENROLLMENT
A25: Not Started | B25: =IF('Document & Task Library'!C37="","",'Document & Task Library'!C37) -> Complete Enrollment - CancerCare | C25: =IF('Document & Task Library'!H37="","",'Document & Task Library'!H37) -> Activates CancerCare for your members | D25: =IF('Document & Task Library'!E37="ALWAYS","Yes",IFERROR(INDEX('Client Setup'!$D$12:$D$38,MATCH('Document & Task Library'!E37,'Client Setup'!$B$12:$B$38,0)),"No")) -> No
B26: ="Why it matters: "&'Document & Task Library'!I37&" What to expect: "&'Document & Task Library'!J37 -> Why it matters: Finalize the eligibility feed and member enrollment setup with CancerCare so the solution is active for members at go-live. What to expect: Coordinated on the vendor kickoff call above; exact timing varies by vendor.
A27: Not Started | B27: =IF('Document & Task Library'!C38="","",'Document & Task Library'!C38) -> Complete Enrollment - eHealth | C27: =IF('Document & Task Library'!H38="","",'Document & Task Library'!H38) -> Activates eHealth for your members | D27: =IF('Document & Task Library'!E38="ALWAYS","Yes",IFERROR(INDEX('Client Setup'!$D$12:$D$38,MATCH('Document & Task Library'!E38,'Client Setup'!$B$12:$B$38,0)),"No")) -> No
B28: ="Why it matters: "&'Document & Task Library'!I38&" What to expect: "&'Document & Task Library'!J38 -> Why it matters: Finalize the eligibility feed and member enrollment setup with eHealth so the solution is active for members at go-live. What to expect: Coordinated on the vendor kickoff call above; exact timing varies by vendor.
A29: Not Started | B29: =IF('Document & Task Library'!C39="","",'Document & Task Library'!C39) -> Complete Enrollment - First Stop Health | C29: =IF('Document & Task Library'!H39="","",'Document & Task Library'!H39) -> Activates First Stop Health for your members | D29: =IF('Document & Task Library'!E39="ALWAYS","Yes",IFERROR(INDEX('Client Setup'!$D$12:$D$38,MATCH('Document & Task Library'!E39,'Client Setup'!$B$12:$B$38,0)),"No")) -> No
B30: ="Why it matters: "&'Document & Task Library'!I39&" What to expect: "&'Document & Task Library'!J39 -> Why it matters: Finalize the eligibility feed and member enrollment setup with First Stop Health so the solution is active for members at go-live. What to expect: Coordinated on the vendor kickoff call above; exact timing varies by vendor.
A31: Not Started | B31: =IF('Document & Task Library'!C40="","",'Document & Task Library'!C40) -> Complete Enrollment - Found | C31: =IF('Document & Task Library'!H40="","",'Document & Task Library'!H40) -> Activates Found for your members | D31: =IF('Document & Task Library'!E40="ALWAYS","Yes",IFERROR(INDEX('Client Setup'!$D$12:$D$38,MATCH('Document & Task Library'!E40,'Client Setup'!$B$12:$B$38,0)),"No")) -> No
B32: ="Why it matters: "&'Document & Task Library'!I40&" What to expect: "&'Document & Task Library'!J40 -> Why it matters: Finalize the eligibility feed and member enrollment setup with Found so the solution is active for members at go-live. What to expect: Coordinated on the vendor kickoff call above; exact timing varies by vendor.
A33: Not Started | B33: =IF('Document & Task Library'!C41="","",'Document & Task Library'!C41) -> Complete Enrollment - HUSK | C33: =IF('Document & Task Library'!H41="","",'Document & Task Library'!H41) -> Activates HUSK for your members | D33: =IF('Document & Task Library'!E41="ALWAYS","Yes",IFERROR(INDEX('Client Setup'!$D$12:$D$38,MATCH('Document & Task Library'!E41,'Client Setup'!$B$12:$B$38,0)),"No")) -> No
B34: ="Why it matters: "&'Document & Task Library'!I41&" What to expect: "&'Document & Task Library'!J41 -> Why it matters: Finalize the eligibility feed and member enrollment setup with HUSK so the solution is active for members at go-live. What to expect: Coordinated on the vendor kickoff call above; exact timing varies by vendor.
A35: Not Started | B35: =IF('Document & Task Library'!C42="","",'Document & Task Library'!C42) -> Complete Enrollment - Lyra Select | C35: =IF('Document & Task Library'!H42="","",'Document & Task Library'!H42) -> Activates Lyra Select for your members | D35: =IF('Document & Task Library'!E42="ALWAYS","Yes",IFERROR(INDEX('Client Setup'!$D$12:$D$38,MATCH('Document & Task Library'!E42,'Client Setup'!$B$12:$B$38,0)),"No")) -> No
B36: ="Why it matters: "&'Document & Task Library'!I42&" What to expect: "&'Document & Task Library'!J42 -> Why it matters: Finalize the eligibility feed and member enrollment setup with Lyra Select so the solution is active for members at go-live. What to expect: Coordinated on the vendor kickoff call above; exact timing varies by vendor.
A37: Not Started | B37: =IF('Document & Task Library'!C43="","",'Document & Task Library'!C43) -> Complete Enrollment - The Phia Group | C37: =IF('Document & Task Library'!H43="","",'Document & Task Library'!H43) -> Activates The Phia Group for your members | D37: =IF('Document & Task Library'!E43="ALWAYS","Yes",IFERROR(INDEX('Client Setup'!$D$12:$D$38,MATCH('Document & Task Library'!E43,'Client Setup'!$B$12:$B$38,0)),"No")) -> No
B38: ="Why it matters: "&'Document & Task Library'!I43&" What to expect: "&'Document & Task Library'!J43 -> Why it matters: Finalize the eligibility feed and member enrollment setup with The Phia Group so the solution is active for members at go-live. What to expect: Coordinated on the vendor kickoff call above; exact timing varies by vendor.
A39: Not Started | B39: =IF('Document & Task Library'!C44="","",'Document & Task Library'!C44) -> Complete Enrollment - Progeny Health | C39: =IF('Document & Task Library'!H44="","",'Document & Task Library'!H44) -> Activates Progeny Health for your members | D39: =IF('Document & Task Library'!E44="ALWAYS","Yes",IFERROR(INDEX('Client Setup'!$D$12:$D$38,MATCH('Document & Task Library'!E44,'Client Setup'!$B$12:$B$38,0)),"No")) -> No
B40: ="Why it matters: "&'Document & Task Library'!I44&" What to expect: "&'Document & Task Library'!J44 -> Why it matters: Finalize the eligibility feed and member enrollment setup with Progeny Health so the solution is active for members at go-live. What to expect: Coordinated on the vendor kickoff call above; exact timing varies by vendor.
A41: Not Started | B41: =IF('Document & Task Library'!C45="","",'Document & Task Library'!C45) -> Complete Enrollment - Renalogic | C41: =IF('Document & Task Library'!H45="","",'Document & Task Library'!H45) -> Activates Renalogic for your members | D41: =IF('Document & Task Library'!E45="ALWAYS","Yes",IFERROR(INDEX('Client Setup'!$D$12:$D$38,MATCH('Document & Task Library'!E45,'Client Setup'!$B$12:$B$38,0)),"No")) -> No
...

Sheet Finance Checklist
A1: Finance Checklist
A2: ="Prepared for "&'Client Setup'!$C$4&" | "&'Client Setup'!$C$8 -> Prepared for Example Employer, Inc. | New to Self-Funding
A3: Banking setup and funding calls. Once Setup is finished, click the Applicable filter above and choose Yes to hide anything that doesn't apply.
A5: Status | B5: Item | C5: What This Covers | D5: Applicable? | E5: Due Date
A6: 1. KICKOFF & IMPLEMENTATION CALLS
A7: Not Started | B7: =IF('Document & Task Library'!C9="","",'Document & Task Library'!C9) -> Banking Implementation Calls | C7: =IF('Document & Task Library'!H9="","",'Document & Task Library'!H9) -> Sets up claims funding with your TPA and bank | D7: =IF('Document & Task Library'!E9="ALWAYS","Yes",IFERROR(INDEX('Client Setup'!$D$12:$D$38,MATCH('Document & Task Library'!E9,'Client Setup'!$B$12:$B$38,0)),"No")) -> Yes
B8: ="Why it matters: "&'Document & Task Library'!I9&" What to expect: "&'Document & Task Library'!J9 -> Why it matters: Calls with the TPA and bank to set up the claims funding account, wire/ACH authorization, and daily funding process. What to expect: 1-2 calls. Finance should have bank signer authorization ready in advance.
A9: Not Started | B9: =IF('Document & Task Library'!C10="","",'Document & Task Library'!C10) -> Coverage Determination Calls (Optional) | C9: =IF('Document & Task Library'!H10="","",'Document & Task Library'!H10) -> Optional review of how high-cost claims will be paid | D9: =IF('Document & Task Library'!E10="ALWAYS","Yes",IFERROR(INDEX('Client Setup'!$D$12:$D$38,MATCH('Document & Task Library'!E10,'Client Setup'!$B$12:$B$38,0)),"No")) -> No
B10: ="Why it matters: "&'Document & Task Library'!I10&" What to expect: "&'Document & Task Library'!J10 -> Why it matters: Optional calls where Finance reviews how specific high-cost claims will be adjudicated under the new plan design. What to expect: Scheduled only if Finance opts in on the Setup tab; typically one call.
A11: 2. DOCUMENTS TO SIGN
A12: Not Started | B12: =IF('Document & Task Library'!C17="","",'Document & Task Library'!C17) -> Captive Capital Invoice | C12: =IF('Document & Task Library'!H17="","",'Document & Task Library'!H17) -> Your required capital contribution to the captive | D12: =IF('Document & Task Library'!E17="ALWAYS","Yes",IFERROR(INDEX('Client Setup'!$D$12:$D$38,MATCH('Document & Task Library'!E17,'Client Setup'!$B$12:$B$38,0)),"No")) -> No
B13: ="Why it matters: "&'Document & Task Library'!I17&" What to expect: "&'Document & Task Library'!J17 -> Why it matters: Invoice for the client's required capital contribution to the captive, a standard condition of participation. What to expect: Payment due date is tied to the plan effective date. Confirm wire instructions with Finance before sending funds.
A14: 4. FINANCE WORKSTREAM
A15: Not Started | B15: =IF('Document & Task Library'!C35="","",'Document & Task Library'!C35) -> Establish Bank Account for Benefits | C15: =IF('Document & Task Library'!H35="","",'Document & Task Library'!H35) -> Opens the account that funds claims payments | D15: =IF('Document & Task Library'!E35="ALWAYS","Yes",IFERROR(INDEX('Client Setup'!$D$12:$D$38,MATCH('Document & Task Library'!E35,'Client Setup'!$B$12:$B$38,0)),"No")) -> Yes
B16: ="Why it matters: "&'Document & Task Library'!I35&" What to expect: "&'Document & Task Library'!J35 -> Why it matters: Open the dedicated bank account used to fund claims payments under the self-funded plan. What to expect: Banks typically need 5-10 business days. Start this early.
A17: Not Started | B17: =IF('Document & Task Library'!C36="","",'Document & Task Library'!C36) -> Review Sample Check Registers | C17: =IF('Document & Task Library'!H36="","",'Document & Task Library'!H36) -> Confirms your claims funding and reporting format | D17: =IF('Document & Task Library'!E36="ALWAYS","Yes",IFERROR(INDEX('Client Setup'!$D$12:$D$38,MATCH('Document & Task Library'!E36,'Client Setup'!$B$12:$B$38,0)),"No")) -> Yes
B18: ="Why it matters: "&'Document & Task Library'!I36&" What to expect: "&'Document & Task Library'!J36 -> Why it matters: Review sample TPA check registers to confirm the funding and reporting format Finance will receive going forward. What to expect: One-time review that sets up Finance's ongoing reconciliation process.

Sheet Signing Checklist
A1: Signing Checklist
A2: ="Prepared for "&'Client Setup'!$C$4&" | "&'Client Setup'!$C$8 -> Prepared for Example Employer, Inc. | New to Self-Funding
A3: Every document below is signed by your CFO or Authorized Signer. Once Setup is finished, click the Applicable filter above and choose Yes to hide anything that doesn't apply.
A5: Status | B5: Item | C5: What This Covers | D5: Applicable? | E5: Due Date
A6: 2. DOCUMENTS TO SIGN
A7: Not Started | B7: =IF('Document & Task Library'!C11="","",'Document & Task Library'!C11) -> TPA Admin Service Agreement | C7: =IF('Document & Task Library'!H11="","",'Document & Task Library'!H11) -> The core contract governing claims administration | D7: =IF('Document & Task Library'!E11="ALWAYS","Yes",IFERROR(INDEX('Client Setup'!$D$12:$D$38,MATCH('Document & Task Library'!E11,'Client Setup'!$B$12:$B$38,0)),"No")) -> Yes
B8: ="Why it matters: "&'Document & Task Library'!I11&" What to expect: "&'Document & Task Library'!J11 -> Why it matters: The core administrative services contract with the Third Party Administrator. It governs claims processing, customer service, and reporting for the life of the agreement. What to expect: Legal/CFO review is recommended. Typical turnaround is 5-10 business days once terms are finalized.
A9: Not Started | B9: =IF('Document & Task Library'!C12="","",'Document & Task Library'!C12) -> Stop-Loss Quote | C9: =IF('Document & Task Library'!H12="","",'Document & Task Library'!H12) -> Locks in your stop-loss pricing and terms | D9: =IF('Document & Task Library'!E12="ALWAYS","Yes",IFERROR(INDEX('Client Setup'!$D$12:$D$38,MATCH('Document & Task Library'!E12,'Client Setup'!$B$12:$B$38,0)),"No")) -> Yes
B10: ="Why it matters: "&'Document & Task Library'!I12&" What to expect: "&'Document & Task Library'!J12 -> Why it matters: The formal quote from the stop-loss carrier confirming premium, specific and aggregate deductibles, and contract basis (paid/incurred vs. incurred/paid). What to expect: Signature confirms acceptance of terms and locks in pricing. Usually due within 5-10 business days of receipt to hold the rate.
A11: Not Started | B11: =IF('Document & Task Library'!C13="","",'Document & Task Library'!C13) -> Stop-Loss Policy | C11: =IF('Document & Task Library'!H13="","",'Document & Task Library'!H13) -> The binding policy that pays claims above deductible | D11: =IF('Document & Task Library'!E13="ALWAYS","Yes",IFERROR(INDEX('Client Setup'!$D$12:$D$38,MATCH('Document & Task Library'!E13,'Client Setup'!$B$12:$B$38,0)),"No")) -> Yes
B12: ="Why it matters: "&'Document & Task Library'!I13&" What to expect: "&'Document & Task Library'!J13 -> Why it matters: The binding insurance policy issued after the quote is accepted. This is the legal contract that pays claims above the deductible. What to expect: Issued after the quote is signed and the plan is bound. Review against the quote for accuracy.
A13: Not Started | B13: =IF('Document & Task Library'!C14="","",'Document & Task Library'!C14) -> PBM Master Agreement | C13: =IF('Document & Task Library'!H14="","",'Document & Task Library'!H14) -> Governs pharmacy pricing and rebate terms | D13: =IF('Document & Task Library'!E14="ALWAYS","Yes",IFERROR(INDEX('Client Setup'!$D$12:$D$38,MATCH('Document & Task Library'!E14,'Client Setup'!$B$12:$B$38,0)),"No")) -> Yes
B14: ="Why it matters: "&'Document & Task Library'!I14&" What to expect: "&'Document & Task Library'!J14 -> Why it matters: The contract governing pharmacy claims processing, pricing guarantees, and rebate terms with the Pharmacy Benefit Manager. What to expect: Often the longest document in the packet. CFO/Authorized Signer review is recommended before signing.
A15: Not Started | B15: =IF('Document & Task Library'!C15="","",'Document & Task Library'!C15) -> PBM Implementation Manual | C15: =IF('Document & Task Library'!H15="","",'Document & Task Library'!H15) -> Confirms formulary and prior authorization rules | D15: =IF('Document & Task Library'!E15="ALWAYS","Yes",IFERROR(INDEX('Client Setup'!$D$12:$D$38,MATCH('Document & Task Library'!E15,'Client Setup'!$B$12:$B$38,0)),"No")) -> Yes
B16: ="Why it matters: "&'Document & Task Library'!I15&" What to expect: "&'Document & Task Library'!J15 -> Why it matters: Operational reference confirming formulary, prior authorization criteria, and member communication timelines for go-live. What to expect: Typically an acknowledgment signature, not a negotiated contract.
A17: Not Started | B17: =IF('Document & Task Library'!C16="","",'Document & Task Library'!C16) -> Captive Agreement | C17: =IF('Document & Task Library'!H16="","",'Document & Task Library'!H16) -> Governs your participation in the group captive | D17: =IF('Document & Task Library'!E16="ALWAYS","Yes",IFERROR(INDEX('Client Setup'!$D$12:$D$38,MATCH('Document & Task Library'!E16,'Client Setup'!$B$12:$B$38,0)),"No")) -> No
B18: ="Why it matters: "&'Document & Task Library'!I16&" What to expect: "&'Document & Task Library'!J16 -> Why it matters: The governing agreement (100+ pages) for participation in the group captive, covering member obligations, loss fund mechanics, and governance. What to expect: The most detailed document in the packet. Budget extra review time; CCIG can walk through the key sections before signing.
A19: Not Started | B19: =IF('Document & Task Library'!C17="","",'Document & Task Library'!C17) -> Captive Capital Invoice | C19: =IF('Document & Task Library'!H17="","",'Document & Task Library'!H17) -> Your required capital contribution to the captive | D19: =IF('Document & Task Library'!E17="ALWAYS","Yes",IFERROR(INDEX('Client Setup'!$D$12:$D$38,MATCH('Document & Task Library'!E17,'Client Setup'!$B$12:$B$38,0)),"No")) -> No
B20: ="Why it matters: "&'Document & Task Library'!I17&" What to expect: "&'Document & Task Library'!J17 -> Why it matters: Invoice for the client's required capital contribution to the captive, a standard condition of participation. What to expect: Payment due date is tied to the plan effective date. Confirm wire instructions with Finance before sending funds.
A21: Not Started | B21: =IF('Document & Task Library'!C18="","",'Document & Task Library'!C18) -> Savings Engine Agreement - CancerCare | C21: =IF('Document & Task Library'!H18="","",'Document & Task Library'!H18) -> Enrollment agreement with CancerCare | D21: =IF('Document & Task Library'!E18="ALWAYS","Yes",IFERROR(INDEX('Client Setup'!$D$12:$D$38,MATCH('Document & Task Library'!E18,'Client Setup'!$B$12:$B$38,0)),"No")) -> No
B22: ="Why it matters: "&'Document & Task Library'!I18&" What to expect: "&'Document & Task Library'!J18 -> Why it matters: Enrollment/services agreement with CancerCare, cancer care navigation and second-opinion support for members with a cancer diagnosis. What to expect: Signature authorizes data sharing and enrollment. Turnaround varies by vendor; confirm on the vendor kickoff call.
A23: Not Started | B23: =IF('Document & Task Library'!C19="","",'Document & Task Library'!C19) -> Savings Engine Agreement - eHealth | C23: =IF('Document & Task Library'!H19="","",'Document & Task Library'!H19) -> Enrollment agreement with eHealth | D23: =IF('Document & Task Library'!E19="ALWAYS","Yes",IFERROR(INDEX('Client Setup'!$D$12:$D$38,MATCH('Document & Task Library'!E19,'Client Setup'!$B$12:$B$38,0)),"No")) -> No
B24: ="Why it matters: "&'Document & Task Library'!I19&" What to expect: "&'Document & Task Library'!J19 -> Why it matters: Enrollment/services agreement with eHealth, Medicare and ACA marketplace enrollment support, commonly used for retirees or employees losing group coverage. What to expect: Signature authorizes data sharing and enrollment. Turnaround varies by vendor; confirm on the vendor kickoff call.
A25: Not Started | B25: =IF('Document & Task Library'!C20="","",'Document & Task Library'!C20) -> Savings Engine Agreement - First Stop Health | C25: =IF('Document & Task Library'!H20="","",'Document & Task Library'!H20) -> Enrollment agreement with First Stop Health | D25: =IF('Document & Task Library'!E20="ALWAYS","Yes",IFERROR(INDEX('Client Setup'!$D$12:$D$38,MATCH('Document & Task Library'!E20,'Client Setup'!$B$12:$B$38,0)),"No")) -> No
B26: ="Why it matters: "&'Document & Task Library'!I20&" What to expect: "&'Document & Task Library'!J20 -> Why it matters: Enrollment/services agreement with First Stop Health, 24/7 virtual primary and urgent care, giving members phone or video access to a doctor. What to expect: Signature authorizes data sharing and enrollment. Turnaround varies by vendor; confirm on the vendor kickoff call.
A27: Not Started | B27: =IF('Document & Task Library'!C21="","",'Document & Task Library'!C21) -> Savings Engine Agreement - Found | C27: =IF('Document & Task Library'!H21="","",'Document & Task Library'!H21) -> Enrollment agreement with Found | D27: =IF('Document & Task Library'!E21="ALWAYS","Yes",IFERROR(INDEX('Client Setup'!$D$12:$D$38,MATCH('Document & Task Library'!E21,'Client Setup'!$B$12:$B$38,0)),"No")) -> No
B28: ="Why it matters: "&'Document & Task Library'!I21&" What to expect: "&'Document & Task Library'!J21 -> Why it matters: Enrollment/services agreement with Found, a physician-led weight management program pairing GLP-1 medication access with coaching, aimed at controlling GLP-1 drug spend. What to expect: Signature authorizes data sharing and enrollment. Turnaround varies by vendor; confirm on the vendor kickoff call.
A29: Not Started | B29: =IF('Document & Task Library'!C22="","",'Document & Task Library'!C22) -> Savings Engine Agreement - HUSK | C29: =IF('Document & Task Library'!H22="","",'Document & Task Library'!H22) -> Enrollment agreement with HUSK | D29: =IF('Document & Task Library'!E22="ALWAYS","Yes",IFERROR(INDEX('Client Setup'!$D$12:$D$38,MATCH('Document & Task Library'!E22,'Client Setup'!$B$12:$B$38,0)),"No")) -> No
B30: ="Why it matters: "&'Document & Task Library'!I22&" What to expect: "&'Document & Task Library'!J22 -> Why it matters: Enrollment/services agreement with HUSK, a wellness ecosystem covering nutrition counseling, mental health support, and incentive rewards. What to expect: Signature authorizes data sharing and enrollment. Turnaround varies by vendor; confirm on the vendor kickoff call.
A31: Not Started | B31: =IF('Document & Task Library'!C23="","",'Document & Task Library'!C23) -> Savings Engine Agreement - Lyra Select | C31: =IF('Document & Task Library'!H23="","",'Document & Task Library'!H23) -> Enrollment agreement with Lyra Select | D31: =IF('Document & Task Library'!E23="ALWAYS","Yes",IFERROR(INDEX('Client Setup'!$D$12:$D$38,MATCH('Document & Task Library'!E23,'Client Setup'!$B$12:$B$38,0)),"No")) -> No
B32: ="Why it matters: "&'Document & Task Library'!I23&" What to expect: "&'Document & Task Library'!J23 -> Why it matters: Enrollment/services agreement with Lyra Select, a mental health benefit connecting members to therapy and coaching. What to expect: Signature authorizes data sharing and enrollment. Turnaround varies by vendor; confirm on the vendor kickoff call.
A33: Not Started | B33: =IF('Document & Task Library'!C24="","",'Document & Task Library'!C24) -> Savings Engine Agreement - The Phia Group | C33: =IF('Document & Task Library'!H24="","",'Document & Task Library'!H24) -> Enrollment agreement with The Phia Group | D33: =IF('Document & Task Library'!E24="ALWAYS","Yes",IFERROR(INDEX('Client Setup'!$D$12:$D$38,MATCH('Document & Task Library'!E24,'Client Setup'!$B$12:$B$38,0)),"No")) -> No
B34: ="Why it matters: "&'Document & Task Library'!I24&" What to expect: "&'Document & Task Library'!J24 -> Why it matters: Enrollment/services agreement with The Phia Group, benefit compliance and subrogation support, helping recover costs from third parties and reduce plan liability. What to expect: Signature authorizes data sharing and enrollment. Turnaround varies by vendor; confirm on the vendor kickoff call.
A35: Not Started | B35: =IF('Document & Task Library'!C25="","",'Document & Task Library'!C25) -> Savings Engine Agreement - Progeny Health | C35: =IF('Document & Task Library'!H25="","",'Document & Task Library'!H25) -> Enrollment agreement with Progeny Health | D35: =IF('Document & Task Library'!E25="ALWAYS","Yes",IFERROR(INDEX('Client Setup'!$D$12:$D$38,MATCH('Document & Task Library'!E25,'Client Setup'!$B$12:$B$38,0)),"No")) -> No
B36: ="Why it matters: "&'Document & Task Library'!I25&" What to expect: "&'Document & Task Library'!J25 -> Why it matters: Enrollment/services agreement with Progeny Health, specialized case management for babies in the NICU, aimed at improving outcomes and controlling neonatal claim costs. What to expect: Signature authorizes data sharing and enrollment. Turnaround varies by vendor; confirm on the vendor kickoff call.
A37: Not Started | B37: =IF('Document & Task Library'!C26="","",'Document & Task Library'!C26) -> Savings Engine Agreement - Renalogic | C37: =IF('Document & Task Library'!H26="","",'Document & Task Library'!H26) -> Enrollment agreement with Renalogic | D37: =IF('Document & Task Library'!E26="ALWAYS","Yes",IFERROR(INDEX('Client Setup'!$D$12:$D$38,MATCH('Document & Task Library'!E26,'Client Setup'!$B$12:$B$38,0)),"No")) -> No
B38: ="Why it matters: "&'Document & Task Library'!I26&" What to expect: "&'Document & Task Library'!J26 -> Why it matters: Enrollment/services agreement with Renalogic, chronic kidney disease and dialysis cost management, identifying at-risk members early and steering care to lower-cost, in-network dialysis providers. What to expect: Signature authorizes data sharing and enrollment. Turnaround varies by vendor; confirm on the vendor kickoff call.
A39: Not Started | B39: =IF('Document & Task Library'!C27="","",'Document & Task Library'!C27) -> Savings Engine Agreement - Rightway | C39: =IF('Document & Task Library'!H27="","",'Document & Task Library'!H27) -> Enrollment agreement with Rightway | D39: =IF('Document & Task Library'!E27="ALWAYS","Yes",IFERROR(INDEX('Client Setup'!$D$12:$D$38,MATCH('Document & Task Library'!E27,'Client Setup'!$B$12:$B$38,0)),"No")) -> No
B40: ="Why it matters: "&'Document & Task Library'!I27&" What to expect: "&'Document & Task Library'!J27 -> Why it matters: Enrollment/services agreement with Rightway, care navigation and pharmacy guidance, helping members find in-network providers and compare costs for surgeries, imaging, and prescriptions. What to expect: Signature authorizes data sharing and enrollment. Turnaround varies by vendor; confirm on the vendor kickoff call.
A41: Not Started | B41: =IF('Document & Task Library'!C28="","",'Document & Task Library'!C28) -> Savings Engine Agreement - SmartConnect (powered by SmartMatch) | C41: =IF('Document & Task Library'!H28="","",'Document & Task Library'!H28) -> Enrollment agreement with SmartConnect (powered by SmartMatch) | D41: =IF('Document & Task Library'!E28="ALWAYS","Yes",IFERROR(INDEX('Client Setup'!$D$12:$D$38,MATCH('Document & Task Library'!E28,'Client Setup'!$B$12:$B$38,0)),"No")) -> No
...

Sheet Full Roadmap
A1: Full Roadmap
A2: ="Prepared for "&'Client Setup'!$C$4&" | "&'Client Setup'!$C$8 -> Prepared for Example Employer, Inc. | New to Self-Funding
A3: Everything in one place: calls, documents, and tasks across every team. Once Setup is finished, click the Applicable filter above and choose Yes to hide anything that doesn't apply.
A5: Status | B5: Item | C5: What This Covers | D5: Responsible Party | E5: Signer | F5: Applicable? | G5: Due Date
A6: 1. KICKOFF & IMPLEMENTATION CALLS
A7: Not Started | B7: =IF('Document & Task Library'!C5="","",'Document & Task Library'!C5) -> TPA & Benefit Design Calls | C7: =IF('Document & Task Library'!H5="","",'Document & Task Library'!H5) -> Finalizes plan design and claims setup with your TPA | D7: =IF('Document & Task Library'!F5="","",'Document & Task Library'!F5) -> Client HR + CCIG | E7: =IF('Document & Task Library'!G5="","",'Document & Task Library'!G5) | F7: =IF('Document & Task Library'!E5="ALWAYS","Yes",IFERROR(INDEX('Client Setup'!$D$12:$D$38,MATCH('Document & Task Library'!E5,'Client Setup'!$B$12:$B$38,0)),"No")) -> Yes
B8: ="Why it matters: "&'Document & Task Library'!I5&" What to expect: "&'Document & Task Library'!J5 -> Why it matters: Kickoff calls with the Third Party Administrator to finalize plan design, eligibility rules, and claims administration setup ahead of the effective date. What to expect: 2-4 sessions of 60-90 minutes over the first 3-4 weeks. Have current plan documents and eligibility file specs ready.
A9: Not Started | B9: =IF('Document & Task Library'!C6="","",'Document & Task Library'!C6) -> PBM Implementation Calls | C9: =IF('Document & Task Library'!H6="","",'Document & Task Library'!H6) -> Sets up your pharmacy formulary and member ID cards | D9: =IF('Document & Task Library'!F6="","",'Document & Task Library'!F6) -> Client HR + CCIG | E9: =IF('Document & Task Library'!G6="","",'Document & Task Library'!G6) | F9: =IF('Document & Task Library'!E6="ALWAYS","Yes",IFERROR(INDEX('Client Setup'!$D$12:$D$38,MATCH('Document & Task Library'!E6,'Client Setup'!$B$12:$B$38,0)),"No")) -> Yes
B10: ="Why it matters: "&'Document & Task Library'!I6&" What to expect: "&'Document & Task Library'!J6 -> Why it matters: Implementation calls with the Pharmacy Benefit Manager to configure the formulary, prior authorization rules, and member ID cards. What to expect: 2-3 calls led by the PBM's implementation team. HR confirms member eligibility feed timing.
A11: Not Started | B11: =IF('Document & Task Library'!C7="","",'Document & Task Library'!C7) -> Cost Containment Vendor Calls | C11: =IF('Document & Task Library'!H7="","",'Document & Task Library'!H7) -> Kicks off each Savings Engine vendor you selected | D11: =IF('Document & Task Library'!F7="","",'Document & Task Library'!F7) -> Client HR + CCIG | E11: =IF('Document & Task Library'!G7="","",'Document & Task Library'!G7) | F11: =IF('Document & Task Library'!E7="ALWAYS","Yes",IFERROR(INDEX('Client Setup'!$D$12:$D$38,MATCH('Document & Task Library'!E7,'Client Setup'!$B$12:$B$38,0)),"No")) -> No
B12: ="Why it matters: "&'Document & Task Library'!I7&" What to expect: "&'Document & Task Library'!J7 -> Why it matters: Individual kickoff calls with each selected Savings Engine vendor to set up enrollment, eligibility feeds, and member communications. What to expect: One call per selected vendor, typically 30-45 minutes, scheduled across the first month.
A13: Not Started | B13: =IF('Document & Task Library'!C8="","",'Document & Task Library'!C8) -> COBRA / FSA / HSA Calls | C13: =IF('Document & Task Library'!H8="","",'Document & Task Library'!H8) -> Transitions COBRA and FSA/HSA administration to the new plan | D13: =IF('Document & Task Library'!F8="","",'Document & Task Library'!F8) -> Client HR + CCIG | E13: =IF('Document & Task Library'!G8="","",'Document & Task Library'!G8) | F13: =IF('Document & Task Library'!E8="ALWAYS","Yes",IFERROR(INDEX('Client Setup'!$D$12:$D$38,MATCH('Document & Task Library'!E8,'Client Setup'!$B$12:$B$38,0)),"No")) -> Yes
B14: ="Why it matters: "&'Document & Task Library'!I8&" What to expect: "&'Document & Task Library'!J8 -> Why it matters: Setup calls with the COBRA administrator and FSA/HSA vendor to transition existing participants and establish new account administration. What to expect: One call per vendor. HR provides the current COBRA participant list and FSA/HSA balances for transition.
A15: Not Started | B15: =IF('Document & Task Library'!C9="","",'Document & Task Library'!C9) -> Banking Implementation Calls | C15: =IF('Document & Task Library'!H9="","",'Document & Task Library'!H9) -> Sets up claims funding with your TPA and bank | D15: =IF('Document & Task Library'!F9="","",'Document & Task Library'!F9) -> Client Finance + CCIG | E15: =IF('Document & Task Library'!G9="","",'Document & Task Library'!G9) | F15: =IF('Document & Task Library'!E9="ALWAYS","Yes",IFERROR(INDEX('Client Setup'!$D$12:$D$38,MATCH('Document & Task Library'!E9,'Client Setup'!$B$12:$B$38,0)),"No")) -> Yes
B16: ="Why it matters: "&'Document & Task Library'!I9&" What to expect: "&'Document & Task Library'!J9 -> Why it matters: Calls with the TPA and bank to set up the claims funding account, wire/ACH authorization, and daily funding process. What to expect: 1-2 calls. Finance should have bank signer authorization ready in advance.
A17: Not Started | B17: =IF('Document & Task Library'!C10="","",'Document & Task Library'!C10) -> Coverage Determination Calls (Optional) | C17: =IF('Document & Task Library'!H10="","",'Document & Task Library'!H10) -> Optional review of how high-cost claims will be paid | D17: =IF('Document & Task Library'!F10="","",'Document & Task Library'!F10) -> Client Finance | E17: =IF('Document & Task Library'!G10="","",'Document & Task Library'!G10) | F17: =IF('Document & Task Library'!E10="ALWAYS","Yes",IFERROR(INDEX('Client Setup'!$D$12:$D$38,MATCH('Document & Task Library'!E10,'Client Setup'!$B$12:$B$38,0)),"No")) -> No
B18: ="Why it matters: "&'Document & Task Library'!I10&" What to expect: "&'Document & Task Library'!J10 -> Why it matters: Optional calls where Finance reviews how specific high-cost claims will be adjudicated under the new plan design. What to expect: Scheduled only if Finance opts in on the Setup tab; typically one call.
A19: 2. DOCUMENTS TO SIGN
A20: Not Started | B20: =IF('Document & Task Library'!C11="","",'Document & Task Library'!C11) -> TPA Admin Service Agreement | C20: =IF('Document & Task Library'!H11="","",'Document & Task Library'!H11) -> The core contract governing claims administration | D20: =IF('Document & Task Library'!F11="","",'Document & Task Library'!F11) -> Client Executive/Finance | E20: =IF('Document & Task Library'!G11="","",'Document & Task Library'!G11) -> CFO / Authorized Signer | F20: =IF('Document & Task Library'!E11="ALWAYS","Yes",IFERROR(INDEX('Client Setup'!$D$12:$D$38,MATCH('Document & Task Library'!E11,'Client Setup'!$B$12:$B$38,0)),"No")) -> Yes
B21: ="Why it matters: "&'Document & Task Library'!I11&" What to expect: "&'Document & Task Library'!J11 -> Why it matters: The core administrative services contract with the Third Party Administrator. It governs claims processing, customer service, and reporting for the life of the agreement. What to expect: Legal/CFO review is recommended. Typical turnaround is 5-10 business days once terms are finalized.
A22: Not Started | B22: =IF('Document & Task Library'!C12="","",'Document & Task Library'!C12) -> Stop-Loss Quote | C22: =IF('Document & Task Library'!H12="","",'Document & Task Library'!H12) -> Locks in your stop-loss pricing and terms | D22: =IF('Document & Task Library'!F12="","",'Document & Task Library'!F12) -> Client Executive/Finance | E22: =IF('Document & Task Library'!G12="","",'Document & Task Library'!G12) -> CFO / Authorized Signer | F22: =IF('Document & Task Library'!E12="ALWAYS","Yes",IFERROR(INDEX('Client Setup'!$D$12:$D$38,MATCH('Document & Task Library'!E12,'Client Setup'!$B$12:$B$38,0)),"No")) -> Yes
B23: ="Why it matters: "&'Document & Task Library'!I12&" What to expect: "&'Document & Task Library'!J12 -> Why it matters: The formal quote from the stop-loss carrier confirming premium, specific and aggregate deductibles, and contract basis (paid/incurred vs. incurred/paid). What to expect: Signature confirms acceptance of terms and locks in pricing. Usually due within 5-10 business days of receipt to hold the rate.
A24: Not Started | B24: =IF('Document & Task Library'!C13="","",'Document & Task Library'!C13) -> Stop-Loss Policy | C24: =IF('Document & Task Library'!H13="","",'Document & Task Library'!H13) -> The binding policy that pays claims above deductible | D24: =IF('Document & Task Library'!F13="","",'Document & Task Library'!F13) -> Client Executive/Finance | E24: =IF('Document & Task Library'!G13="","",'Document & Task Library'!G13) -> CFO / Authorized Signer | F24: =IF('Document & Task Library'!E13="ALWAYS","Yes",IFERROR(INDEX('Client Setup'!$D$12:$D$38,MATCH('Document & Task Library'!E13,'Client Setup'!$B$12:$B$38,0)),"No")) -> Yes
B25: ="Why it matters: "&'Document & Task Library'!I13&" What to expect: "&'Document & Task Library'!J13 -> Why it matters: The binding insurance policy issued after the quote is accepted. This is the legal contract that pays claims above the deductible. What to expect: Issued after the quote is signed and the plan is bound. Review against the quote for accuracy.
A26: Not Started | B26: =IF('Document & Task Library'!C14="","",'Document & Task Library'!C14) -> PBM Master Agreement | C26: =IF('Document & Task Library'!H14="","",'Document & Task Library'!H14) -> Governs pharmacy pricing and rebate terms | D26: =IF('Document & Task Library'!F14="","",'Document & Task Library'!F14) -> Client Executive/Finance | E26: =IF('Document & Task Library'!G14="","",'Document & Task Library'!G14) -> CFO / Authorized Signer | F26: =IF('Document & Task Library'!E14="ALWAYS","Yes",IFERROR(INDEX('Client Setup'!$D$12:$D$38,MATCH('Document & Task Library'!E14,'Client Setup'!$B$12:$B$38,0)),"No")) -> Yes
B27: ="Why it matters: "&'Document & Task Library'!I14&" What to expect: "&'Document & Task Library'!J14 -> Why it matters: The contract governing pharmacy claims processing, pricing guarantees, and rebate terms with the Pharmacy Benefit Manager. What to expect: Often the longest document in the packet. CFO/Authorized Signer review is recommended before signing.
A28: Not Started | B28: =IF('Document & Task Library'!C15="","",'Document & Task Library'!C15) -> PBM Implementation Manual | C28: =IF('Document & Task Library'!H15="","",'Document & Task Library'!H15) -> Confirms formulary and prior authorization rules | D28: =IF('Document & Task Library'!F15="","",'Document & Task Library'!F15) -> Client Executive/Finance | E28: =IF('Document & Task Library'!G15="","",'Document & Task Library'!G15) -> CFO / Authorized Signer | F28: =IF('Document & Task Library'!E15="ALWAYS","Yes",IFERROR(INDEX('Client Setup'!$D$12:$D$38,MATCH('Document & Task Library'!E15,'Client Setup'!$B$12:$B$38,0)),"No")) -> Yes
B29: ="Why it matters: "&'Document & Task Library'!I15&" What to expect: "&'Document & Task Library'!J15 -> Why it matters: Operational reference confirming formulary, prior authorization criteria, and member communication timelines for go-live. What to expect: Typically an acknowledgment signature, not a negotiated contract.
A30: Not Started | B30: =IF('Document & Task Library'!C16="","",'Document & Task Library'!C16) -> Captive Agreement | C30: =IF('Document & Task Library'!H16="","",'Document & Task Library'!H16) -> Governs your participation in the group captive | D30: =IF('Document & Task Library'!F16="","",'Document & Task Library'!F16) -> Client Executive/Finance | E30: =IF('Document & Task Library'!G16="","",'Document & Task Library'!G16) -> CFO / Authorized Signer | F30: =IF('Document & Task Library'!E16="ALWAYS","Yes",IFERROR(INDEX('Client Setup'!$D$12:$D$38,MATCH('Document & Task Library'!E16,'Client Setup'!$B$12:$B$38,0)),"No")) -> No
B31: ="Why it matters: "&'Document & Task Library'!I16&" What to expect: "&'Document & Task Library'!J16 -> Why it matters: The governing agreement (100+ pages) for participation in the group captive, covering member obligations, loss fund mechanics, and governance. What to expect: The most detailed document in the packet. Budget extra review time; CCIG can walk through the key sections before signing.
A32: Not Started | B32: =IF('Document & Task Library'!C17="","",'Document & Task Library'!C17) -> Captive Capital Invoice | C32: =IF('Document & Task Library'!H17="","",'Document & Task Library'!H17) -> Your required capital contribution to the captive | D32: =IF('Document & Task Library'!F17="","",'Document & Task Library'!F17) -> Client Finance | E32: =IF('Document & Task Library'!G17="","",'Document & Task Library'!G17) -> CFO / Authorized Signer | F32: =IF('Document & Task Library'!E17="ALWAYS","Yes",IFERROR(INDEX('Client Setup'!$D$12:$D$38,MATCH('Document & Task Library'!E17,'Client Setup'!$B$12:$B$38,0)),"No")) -> No
B33: ="Why it matters: "&'Document & Task Library'!I17&" What to expect: "&'Document & Task Library'!J17 -> Why it matters: Invoice for the client's required capital contribution to the captive, a standard condition of participation. What to expect: Payment due date is tied to the plan effective date. Confirm wire instructions with Finance before sending funds.
A34: Not Started | B34: =IF('Document & Task Library'!C18="","",'Document & Task Library'!C18) -> Savings Engine Agreement - CancerCare | C34: =IF('Document & Task Library'!H18="","",'Document & Task Library'!H18) -> Enrollment agreement with CancerCare | D34: =IF('Document & Task Library'!F18="","",'Document & Task Library'!F18) -> Client Executive/Finance | E34: =IF('Document & Task Library'!G18="","",'Document & Task Library'!G18) -> CFO / Authorized Signer | F34: =IF('Document & Task Library'!E18="ALWAYS","Yes",IFERROR(INDEX('Client Setup'!$D$12:$D$38,MATCH('Document & Task Library'!E18,'Client Setup'!$B$12:$B$38,0)),"No")) -> No
B35: ="Why it matters: "&'Document & Task Library'!I18&" What to expect: "&'Document & Task Library'!J18 -> Why it matters: Enrollment/services agreement with CancerCare, cancer care navigation and second-opinion support for members with a cancer diagnosis. What to expect: Signature authorizes data sharing and enrollment. Turnaround varies by vendor; confirm on the vendor kickoff call.
A36: Not Started | B36: =IF('Document & Task Library'!C19="","",'Document & Task Library'!C19) -> Savings Engine Agreement - eHealth | C36: =IF('Document & Task Library'!H19="","",'Document & Task Library'!H19) -> Enrollment agreement with eHealth | D36: =IF('Document & Task Library'!F19="","",'Document & Task Library'!F19) -> Client Executive/Finance | E36: =IF('Document & Task Library'!G19="","",'Document & Task Library'!G19) -> CFO / Authorized Signer | F36: =IF('Document & Task Library'!E19="ALWAYS","Yes",IFERROR(INDEX('Client Setup'!$D$12:$D$38,MATCH('Document & Task Library'!E19,'Client Setup'!$B$12:$B$38,0)),"No")) -> No
B37: ="Why it matters: "&'Document & Task Library'!I19&" What to expect: "&'Document & Task Library'!J19 -> Why it matters: Enrollment/services agreement with eHealth, Medicare and ACA marketplace enrollment support, commonly used for retirees or employees losing group coverage. What to expect: Signature authorizes data sharing and enrollment. Turnaround varies by vendor; confirm on the vendor kickoff call.
A38: Not Started | B38: =IF('Document & Task Library'!C20="","",'Document & Task Library'!C20) -> Savings Engine Agreement - First Stop Health | C38: =IF('Document & Task Library'!H20="","",'Document & Task Library'!H20) -> Enrollment agreement with First Stop Health | D38: =IF('Document & Task Library'!F20="","",'Document & Task Library'!F20) -> Client Executive/Finance | E38: =IF('Document & Task Library'!G20="","",'Document & Task Library'!G20) -> CFO / Authorized Signer | F38: =IF('Document & Task Library'!E20="ALWAYS","Yes",IFERROR(INDEX('Client Setup'!$D$12:$D$38,MATCH('Document & Task Library'!E20,'Client Setup'!$B$12:$B$38,0)),"No")) -> No
B39: ="Why it matters: "&'Document & Task Library'!I20&" What to expect: "&'Document & Task Library'!J20 -> Why it matters: Enrollment/services agreement with First Stop Health, 24/7 virtual primary and urgent care, giving members phone or video access to a doctor. What to expect: Signature authorizes data sharing and enrollment. Turnaround varies by vendor; confirm on the vendor kickoff call.
A40: Not Started | B40: =IF('Document & Task Library'!C21="","",'Document & Task Library'!C21) -> Savings Engine Agreement - Found | C40: =IF('Document & Task Library'!H21="","",'Document & Task Library'!H21) -> Enrollment agreement with Found | D40: =IF('Document & Task Library'!F21="","",'Document & Task Library'!F21) -> Client Executive/Finance | E40: =IF('Document & Task Library'!G21="","",'Document & Task Library'!G21) -> CFO / Authorized Signer | F40: =IF('Document & Task Library'!E21="ALWAYS","Yes",IFERROR(INDEX('Client Setup'!$D$12:$D$38,MATCH('Document & Task Library'!E21,'Client Setup'!$B$12:$B$38,0)),"No")) -> No
B41: ="Why it matters: "&'Document & Task Library'!I21&" What to expect: "&'Document & Task Library'!J21 -> Why it matters: Enrollment/services agreement with Found, a physician-led weight management program pairing GLP-1 medication access with coaching, aimed at controlling GLP-1 drug spend. What to expect: Signature authorizes data sharing and enrollment. Turnaround varies by vendor; confirm on the vendor kickoff call.
...

Sheet Document & Task Library
A1: Document & Task Library - master content, edit here
A2: Source data behind every client-facing tab. Short Line is the scannable one-liner; Description / What to Expect are the full explanation, shown collapsed by default. Vendor blurbs are drafted from general public information - confirm exact scope with CCIG's vendor relationship before client use.
A4: ID | B4: Phase | C4: Item Name | D4: Type | E4: Applies When (Key) | F4: Responsible Party | G4: Signer | H4: Short Line (scannable) | I4: Description - Why It Matters | J4: What to Expect | K4: CCIG Notes
A5: 1 | B5: 1. Kickoff & Implementation Calls | C5: TPA & Benefit Design Calls | D5: Call | E5: ALWAYS | F5: Client HR + CCIG | H5: Finalizes plan design and claims setup with your TPA | I5: Kickoff calls with the Third Party Administrator to finalize plan design, eligibility rules, and claims administration setup ahead of the effective date. | J5: 2-4 sessions of 60-90 minutes over the first 3-4 weeks. Have current plan documents and eligibility file specs ready.
A6: 2 | B6: 1. Kickoff & Implementation Calls | C6: PBM Implementation Calls | D6: Call | E6: PBM | F6: Client HR + CCIG | H6: Sets up your pharmacy formulary and member ID cards | I6: Implementation calls with the Pharmacy Benefit Manager to configure the formulary, prior authorization rules, and member ID cards. | J6: 2-3 calls led by the PBM's implementation team. HR confirms member eligibility feed timing.
A7: 3 | B7: 1. Kickoff & Implementation Calls | C7: Cost Containment Vendor Calls | D7: Call | E7: ANY_CC | F7: Client HR + CCIG | H7: Kicks off each Savings Engine vendor you selected | I7: Individual kickoff calls with each selected Savings Engine vendor to set up enrollment, eligibility feeds, and member communications. | J7: One call per selected vendor, typically 30-45 minutes, scheduled across the first month.
A8: 4 | B8: 1. Kickoff & Implementation Calls | C8: COBRA / FSA / HSA Calls | D8: Call | E8: ALWAYS | F8: Client HR + CCIG | H8: Transitions COBRA and FSA/HSA administration to the new plan | I8: Setup calls with the COBRA administrator and FSA/HSA vendor to transition existing participants and establish new account administration. | J8: One call per vendor. HR provides the current COBRA participant list and FSA/HSA balances for transition.
A9: 5 | B9: 1. Kickoff & Implementation Calls | C9: Banking Implementation Calls | D9: Call | E9: ALWAYS | F9: Client Finance + CCIG | H9: Sets up claims funding with your TPA and bank | I9: Calls with the TPA and bank to set up the claims funding account, wire/ACH authorization, and daily funding process. | J9: 1-2 calls. Finance should have bank signer authorization ready in advance.
A10: 6 | B10: 1. Kickoff & Implementation Calls | C10: Coverage Determination Calls (Optional) | D10: Call | E10: FIN_COVERAGE_CALL | F10: Client Finance | H10: Optional review of how high-cost claims will be paid | I10: Optional calls where Finance reviews how specific high-cost claims will be adjudicated under the new plan design. | J10: Scheduled only if Finance opts in on the Setup tab; typically one call.
A11: 7 | B11: 2. Documents to Sign | C11: TPA Admin Service Agreement | D11: Document | E11: TPA_ADMIN | F11: Client Executive/Finance | G11: CFO / Authorized Signer | H11: The core contract governing claims administration | I11: The core administrative services contract with the Third Party Administrator. It governs claims processing, customer service, and reporting for the life of the agreement. | J11: Legal/CFO review is recommended. Typical turnaround is 5-10 business days once terms are finalized.
A12: 8 | B12: 2. Documents to Sign | C12: Stop-Loss Quote | D12: Document | E12: STOP_LOSS | F12: Client Executive/Finance | G12: CFO / Authorized Signer | H12: Locks in your stop-loss pricing and terms | I12: The formal quote from the stop-loss carrier confirming premium, specific and aggregate deductibles, and contract basis (paid/incurred vs. incurred/paid). | J12: Signature confirms acceptance of terms and locks in pricing. Usually due within 5-10 business days of receipt to hold the rate.
A13: 9 | B13: 2. Documents to Sign | C13: Stop-Loss Policy | D13: Document | E13: STOP_LOSS | F13: Client Executive/Finance | G13: CFO / Authorized Signer | H13: The binding policy that pays claims above deductible | I13: The binding insurance policy issued after the quote is accepted. This is the legal contract that pays claims above the deductible. | J13: Issued after the quote is signed and the plan is bound. Review against the quote for accuracy.
